Workbook
Name Data: 'Kode Produk'!$A$2:$B$796
Name Data_Sales: 'Kode Produk'!$A$2:$A$796
Name Elektronik____Aksesoris_TV___Video: 'Kode Produk'!$A$2:$B$796
Name Kreiteria: 'Kode Produk'!$A$2:$K$796
Name Kriteria: 'Kode Produk'!$A$2:$B$796

Sheet Tata Cara Pengisian
A1: Tata Cara Pengisian Form Tambah Produk
A3: Nama Label | B3: Definisi dan Penggunaan | C3: Nilai Yang Diterima | D3: Contoh | E3: Diharuskan
A4: item_category_id | B4: Diisi otomatis berdasarkan isian di kolom category | C4: Otomatis
A5: category | B5: Kategori barang | C5: Pilih dari dropdown | D5: Elektronik -> Headphone | E5: Wajib
A6: item_group_name | B6: Nama untuk item barang tersebut. | C6: Dapat diisi sesuai dengan keperluan | D6: AIR JORDAN 7 RETRO | E6: Wajib
A7: description | B7: Deskripsi untuk group item tersebut. | C7: Dapat diisi sesuai dengan keperluan. Bisa menggunakan html tags | D7: <p>Sepatu Edisi Spesial </p> | E7: Wajib
A8: package_weight | B8: Berat barang dalam gram | C8: Pengisian hanya menerima format angka | D8: 900 | E8: Wajib
A9: package_length | B9: Panjang paket barang dalam cm | C9: Pengisian hanya menerima format angka | D9: 20 | E9: Bisa Kosong
A10: package_width | B10: Lebar paket barang dalam cm | C10: Pengisian hanya menerima format angka | D10: 20 | E10: Bisa Kosong
A11: package_height | B11: Tinggi paket barang dalam cm | C11: Pengisian hanya menerima format angka | D11: 10 | E11: Bisa Kosong
A12: brand | B12: Merk barang | C12: Diisi seperlunya | D12: Adidas | E12: Bisa Kosong
A13: item_code | B13: Kode unik untuk item barang tersebut. | C13: Dapat diisi sesuai dengan keperluan | D13: SKU-0001 | E13: Wajib
A14: sell_price | B14: Harga jual untuk item barang tersebut. | C14: Pengisian hanya menerima format angka | D14: 1200000 | E14: Wajib (bisa kosong bila melakukan update terhadap item yang sudah ada sebelumnya)
A15: color_variant | B15: Warna variant barang | C15: Diisi bila barang memiliki variant warna | D15: Merah | E15: Bisa Kosong
A16: size_variant | B16: Ukuran variant barang | C16: Diisi bila barang memiliki variant ukuran | D16: XL | E16: Bisa Kosong
A17: capacity_variant | B17: Kapasitas variant barang | C17: Diisi bila barang memiliki variant kapasitas | D17: 32GB | E17: Bisa Kosong
A18: material_variant | B18: Bahan variant barang | C18: Diisi bila barang memiliki variant bahan | D18: Denim | E18: Bisa Kosong
A19: uom_variant | B19: Variasi Satuan barang | C19: Diisi bila barang dijual dengan variant satuan yang berbeda | D19: Lusin | E19: Bisa Kosong
A20: image_url1 | B20: Tautan gambar barang, sekaligus menjadi gambar utama | C20: Diisi tautan gambar bisa berupa tautan http atau https, format gambar jpg atau png | D20: https://s2.bukalapak.com/img/7564553191/m-1000-1000/20171110_110008_scaled.jpg | E20: Bisa Kosong
A21: image_url2 | B21: Tautan gambar barang | C21: Diisi tautan gambar bisa berupa tautan http atau https, format gambar jpg atau png | D21: https://s2.bukalapak.com/img/7564553191/m-1000-1000/20171110_110008_scaled.jpg | E21: Bisa Kosong
A22: image_url3 | B22: Tautan gambar barang | C22: Diisi tautan gambar bisa berupa tautan http atau https, format gambar jpg atau png | D22: https://s2.bukalapak.com/img/7564553191/m-1000-1000/20171110_110008_scaled.jpg | E22: Bisa Kosong
A23: image_url4 | B23: Tautan gambar barang | C23: Diisi tautan gambar bisa berupa tautan http atau https, format gambar jpg atau png | D23: https://s2.bukalapak.com/img/7564553191/m-1000-1000/20171110_110008_scaled.jpg | E23: Bisa Kosong
A24: image_url5 | B24: Tautan gambar barang | C24: Diisi tautan gambar bisa berupa tautan http atau https, format gambar jpg atau png | D24: https://s2.bukalapak.com/img/7564553191/m-1000-1000/20171110_110008_scaled.jpg | E24: Bisa Kosong
A25: default_images | B25: Foto Utama | C25: Jika foto pada salah satu sku dalam suatu produk dianggap sebagai foto utama, mohon tandai dengan kata 'Ya' di sku yang ditujukan, Jika tidak, Jubelio akan secara acak memilih foto lain dalam urutan tersebut sebagai foto utama. | D25: Yes | E25: Bisa Kosong

Sheet Kode Produk
A1: text | B1: id | E1: Warna | G1: Ukuran | I1: Kapasitas | K1: Bahan
A2: Aksesoris Fashion -> Aksesoris & Set Perhiasan -> Bordir | B2: 17876 | E2: Abu-Abu | G2: L | I2: 16GB | K2: Baby Terry
A3: Aksesoris Fashion -> Aksesoris & Set Perhiasan -> Bros | B3: 17875 | E3: Beige | G3: M | I3: 32GB | K3: Balotelli
A4: Aksesoris Fashion -> Aksesoris & Set Perhiasan -> Dasi | B4: 17874 | E4: Biru | G4: S | I4: 64GB | K4: Ceruti
A5: Aksesoris Fashion -> Aksesoris & Set Perhiasan -> Set Perhiasan | B5: 17877 | E5: Coklat | G5: SM | I5: 128GB | K5: Corduroy
A6: Aksesoris Fashion -> Aksesoris & Set Perhiasan -> Tato Temporer | B6: 26818 | E6: Gold | G6: XL | I6: 256GB | K6: Crepe
A7: Aksesoris Fashion -> Aksesoris Rambut -> Bando | B7: 7334 | E7: Hijau | G7: XS | K7: Denim
A8: Aksesoris Fashion -> Aksesoris Rambut -> Bobby Pin | B8: 7335 | E8: Hitam | G8: XXL | K8: Drill
A9: Aksesoris Fashion -> Aksesoris Rambut -> Ikat Rambut | B9: 7336 | E9: Kuning | G9: XXXL | K9: Flanel
A10: Aksesoris Fashion -> Aksesoris Rambut -> Jepit Rambut | B10: 7337 | E10: Merah | G10: All Size | K10: Flannel
A11: Aksesoris Fashion -> Aksesoris Rambut -> Mahkota & Headpiece | B11: 12437 | E11: Nude | G11: 8 | K11: Fleece
A12: Aksesoris Fashion -> Aksesoris Rambut -> Rambut Palsu | B12: 12438 | E12: Orange | G12: 9 | K12: High Twist
A13: Aksesoris Fashion -> Anting -> Anting Hooks | B13: 7329 | E13: Pink | G13: 10 | K13: Hycon
A14: Aksesoris Fashion -> Anting -> Anting Hoops | B14: 7328 | E14: Putih | G14: 11 | K14: Jeans
A15: Aksesoris Fashion -> Anting -> Anting Jepit | B15: 7330 | E15: Silver | G15: 12 | K15: Jersey
A16: Aksesoris Fashion -> Anting -> Anting Magnet | B16: 17865 | E16: Ungu | G16: 13 | K16: Kaos
A17: Aksesoris Fashion -> Anting -> Anting Plug | B17: 17864 | G17: 14 | K17: Katun
A18: Aksesoris Fashion -> Anting -> Anting Stud | B18: 7327 | G18: 15 | K18: Kulit
A19: Aksesoris Fashion -> Cincin -> Cincin Kasual | B19: 17866 | G19: 16 | K19: Kulit Alami
A20: Aksesoris Fashion -> Cincin -> Cincin Tumpuk | B20: 17867 | G20: 17 | K20: Kulit Sintetis
A21: Aksesoris Fashion -> Cincin -> Couple Ring | B21: 7326 | G21: 18 | K21: Lacoste
A22: Aksesoris Fashion -> Gelang -> Bangle | B22: 7321 | G22: 19 | K22: Linen
A23: Aksesoris Fashion -> Gelang -> Gelang Etnik & Bead | B23: 12430 | G23: 20 | K23: Lycra
A24: Aksesoris Fashion -> Gelang -> Gelang Kaki | B24: 17868 | G24: 21 | K24: Parasut
A25: Aksesoris Fashion -> Gelang -> Gelang Kesehatan | B25: 17869 | G25: 22 | K25: Paris
A26: Aksesoris Fashion -> Gelang -> Gelang Mutiara | B26: 7323 | G26: 23 | K26: Pike
A27: Aksesoris Fashion -> Gelang -> Gelang Nama | B27: 12427 | G27: 24 | K27: Polyester
A28: Aksesoris Fashion -> Gelang -> Gelang Tumpuk | B28: 12432 | G28: 25 | K28: Rayon
... A42: Aksesoris Fashion -> Lensa Kontak -> Lensa Bening | B42: 17862 | G42: 39 | K42: Wool
A43: Aksesoris Fashion -> Lensa Kontak -> Lensa Warna | B43: 17863 | G43: 40
A44: Aksesoris Fashion -> Logam Mulia -> Emas | B44: 16882 | G44: 41
A45: Aksesoris Fashion -> Logam Mulia -> Perak | B45: 16705 | G45: 42
A46: Aksesoris Fashion -> Sarung Tangan -> Sarung Tangan Kulit | B46: 12455 | G46: 43
A47: Aksesoris Fashion -> Sarung Tangan -> Sarung Tangan Rajut | B47: 12454 | G47: 44
A48: Aksesoris Fashion -> Sarung Tangan -> Sarung Tangan Renda | B48: 17871 | G48: 45
A49: Aksesoris Fashion -> Syal & Scarf -> Syal Fashion | B49: 12442 | G49: 46
A50: Aksesoris Fashion -> Syal & Scarf -> Syal Rajut | B50: 12445
A51: Aksesoris Fashion -> Syal & Scarf -> Wraps | B51: 17870
A52: Aksesoris Fashion -> Topi -> Fedora | B52: 17860
A53: Aksesoris Fashion -> Topi -> Kupluk | B53: 7340
...

Sheet Pengisian Import Produk
A1: item_category_id | B1: category | C1: item_group_name | D1: description | E1: package_weight | F1: package_length | G1: package_width | H1: package_height | I1: brand | J1: item_code | K1: sell_price | L1: color_variant | M1: size_variant | N1: capacity_variant | O1: material_variant | P1: uom_variant | Q1: barcode | R1: image_url1 | S1: image_url2 | T1: image_url3 | U1: image_url4 | V1: image_url5 | W1: default_images
A2: =IFERROR(VLOOKUP(B2,'Kode Produk'!A:B,2,FALSE), "") -> 17876 | B2: Aksesoris Fashion -> Aksesoris & Set Perhiasan -> Bordir | C2: Sepatu Air Jordan | D2: Sepatu Air Jordan sepatu khusus kamu yang suka bermain basket | E2: 100 | I2: Nike | J2: SKU-00001 | K2: 2000000 | L2: Merah | M2: 45
A3: =IFERROR(VLOOKUP(B3,'Kode Produk'!A:B,2,FALSE), "")
A4: =IFERROR(VLOOKUP(B4,'Kode Produk'!A:B,2,FALSE), "")
A5: =IFERROR(VLOOKUP(B5,'Kode Produk'!A:B,2,FALSE), "")
A6: =IFERROR(VLOOKUP(B6,'Kode Produk'!A:B,2,FALSE), "")
A7: =IFERROR(VLOOKUP(B7,'Kode Produk'!A:B,2,FALSE), "")
A8: =IFERROR(VLOOKUP(B8,'Kode Produk'!A:B,2,FALSE), "")
A9: =IFERROR(VLOOKUP(B9,'Kode Produk'!A:B,2,FALSE), "")
A10: =IFERROR(VLOOKUP(B10,'Kode Produk'!A:B,2,FALSE), "")
A11: =IFERROR(VLOOKUP(B11,'Kode Produk'!A:B,2,FALSE), "")
A12: =IFERROR(VLOOKUP(B12,'Kode Produk'!A:B,2,FALSE), "")
A13: =IFERROR(VLOOKUP(B13,'Kode Produk'!A:B,2,FALSE), "")
A14: =IFERROR(VLOOKUP(B14,'Kode Produk'!A:B,2,FALSE), "")
... A5493: =IFERROR(VLOOKUP(B5493,'Kode Produk'!A:B,2,FALSE), "")
A5494: =IFERROR(VLOOKUP(B5494,'Kode Produk'!A:B,2,FALSE), "") | AD5494: 1
A5495: =IFERROR(VLOOKUP(B5495,'Kode Produk'!A:B,2,FALSE), "")
A5496: =IFERROR(VLOOKUP(B5496,'Kode Produk'!A:B,2,FALSE), "")
A5497: =IFERROR(VLOOKUP(B5497,'Kode Produk'!A:B,2,FALSE), "")
A5498: =IFERROR(VLOOKUP(B5498,'Kode Produk'!A:B,2,FALSE), "")
A5499: =IFERROR(VLOOKUP(B5499,'Kode Produk'!A:B,2,FALSE), "")
A5500: =IFERROR(VLOOKUP(B5500,'Kode Produk'!A:B,2,FALSE), "")
A5501: =IFERROR(VLOOKUP(B5501,'Kode Produk'!A:B,2,FALSE), "")
A5502: =IFERROR(VLOOKUP(B5502,'Kode Produk'!A:B,2,FALSE), "")
A5503: =IFERROR(VLOOKUP(B5503,'Kode Produk'!A:B,2,FALSE), "")
A5504: =IFERROR(VLOOKUP(B5504,'Kode Produk'!A:B,2,FALSE), "")
A5505: =IFERROR(VLOOKUP(B5505,'Kode Produk'!A:B,2,FALSE), "")
A5506: =IFERROR(VLOOKUP(B5506,'Kode Produk'!A:B,2,FALSE), "")
... A6983: =IFERROR(VLOOKUP(B6983,'Kode Produk'!A:B,2,FALSE), "")
